Workbook

Sheet Tabela de ingredientes
A4: Ingredientes | B4: Custo Kg | C4: Açúcares | D4: Gorduras | E4: SNGL | F4: Outros Sólidos | G4: Sólidos Totais | H4: Água | I4: POD | J4: PAC | K4: Proteína | L4: Alergênico
A5: Abacate | B5: 0 | C5: 0.02 | D5: 0.23 | E5: 0 | F5: 0.11 | G5: 0.36 | H5: 0.64 | I5: 0.072 | J5: 0.087 | K5: 0.04 | L5: Não | N5: Parâmetros de tolerância para cada receita:
A6: Abacaxi | B6: 0 | C6: 0.1 | D6: 0 | E6: 0 | F6: 0.04 | G6: 0.14 | H6: 0.86 | I6: 0.16 | J6: 0.2 | K6: 0.01 | L6: Não | N6: Gelato de leite | O6: Açúcares | P6: Gorduras | Q6: SLNG | R6: OS | S6: ST | T6: Água | U6: POD | V6: PAC | X6: Status | Z6: Combinação do Rótulo (Anvisa)
A7: Acerola | B7: 0 | C7: 0.07 | D7: 0 | E7: 0 | F7: 0.01 | G7: 0.08 | H7: 0.92 | I7: 0.08 | J7: 0.1 | K7: 0.006 | L7: Não | N7: Mínimo | O7: 0.14 | P7: 0.05 | Q7: 0.08 | R7: 0 | S7: 0.34 | T7: 0.58 | U7: 135 | V7: 220 | X7: Ok | Z7: Alto em Açúcar Adicionado
A8: Açúcar - Dextrose | B8: 32 | C8: 0.92 | D8: 0 | E8: 0 | F8: 0 | G8: 0.92 | H8: 0.08 | I8: 0.74 | J8: 1.8 | K8: 0 | L8: Não | N8: Máximo | O8: 0.22 | P8: 0.12 | Q8: 0.12 | R8: 0.08 | S8: 0.42 | T8: 0.66 | U8: 200 | V8: 300 | X8: Baixo | Z8: Alto em Gordura Saturada
A9: Açúcar - Frutose | B9: 38 | C9: 1 | D9: 0 | E9: 0 | F9: 0 | G9: 1 | H9: 0 | I9: 1.45 | J9: 1.9 | K9: 0 | L9: Não | N9: Sorbet | O9: Açúcares | P9: Gorduras | Q9: SLNG | R9: OS | S9: ST | T9: Água | U9: POD | V9: PAC | X9: Alto | Z9: Alto em Sódio
A10: Açúcar - Glucose em pó | B10: 38 | C10: 0.95 | D10: 0 | E10: 0 | F10: 0 | G10: 0.95 | H10: 0.05 | I10: 0.4 | J10: 0.7 | K10: 0 | L10: Não | N10: Mínimo | O10: 0.23 | P10: 0 | Q10: 0 | R10: 0.01 | S10: 0.27 | T10: 0.65 | U10: 175 | V10: 275 | Z10: Alto em Açúcar Adicionado e Gordura Saturada
A11: Açúcar - Glucose Líquida | B11: 18 | C11: 0.8 | D11: 0 | E11: 0 | F11: 0 | G11: 0.8 | H11: 0.2 | I11: 0.45 | J11: 0.75 | K11: 0 | L11: Não | N11: Máximo | O11: 0.32 | P11: 0.02 | Q11: 0 | R11: 0.18 | S11: 0.35 | T11: 0.73 | U11: 240 | V11: 375 | Z11: Alto em Açúcar Adicionado e Sódio
A12: Açúcar - Lactose | B12: 45 | C12: 1 | D12: 0 | E12: 0 | F12: 0 | G12: 1 | H12: 0 | I12: 0.16 | J12: 1 | K12: 0 | L12: Sim | N12: Gelato de leite com fruta | O12: Açúcares | P12: Gorduras | Q12: SLNG | R12: OS | S12: ST | T12: Água | U12: POD | V12: PAC | Z12: Alto em Gordura Saturada e Sódio
A13: Açúcar - Maltodextrina | B13: 28 | C13: 0.95 | D13: 0 | E13: 0 | F13: 0 | G13: 0.95 | H13: 0.05 | I13: 0.02 | J13: 0.25 | K13: 0 | L13: Não | N13: Mínimo | O13: 0.17 | P13: 0.04 | Q13: 0.06 | R13: 0.01 | S13: 0.33 | T13: 0.57 | U13: 140 | V13: 220 | Z13: Alto em Açúcar Adicionado, Gordura Saturada e Sódio
A14: Açúcar de maçã(66% açúcar) | B14: 40 | C14: 0.66 | D14: 0 | E14: 0 | F14: 0.33 | G14: 0.99 | H14: 0.01 | I14: 0.85 | J14: =C14*1.9 -> 1.254 | K14: 0.005 | L14: Não | N14: Máximo | O14: 0.22 | P14: 0.08 | Q14: 0.1 | R14: 0.08 | S14: 0.42 | T14: 0.67 | U14: 200 | V14: 300
A15: Açúcar Invertido | B15: 16 | C15: 0.7 | D15: 0 | E15: 0 | F15: 0 | G15: 0.7 | H15: 0.3 | I15: 1.27 | J15: 1.9 | K15: 0 | L15: Não | N15: Base de Água com Chocolate | O15: Açúcares | P15: Gorduras | Q15: SLNG | R15: Os | S15: St | T15: Água | U15: Pod | V15: Pac
A16: Açúcar Sacarose | B16: 4 | C16: 1 | D16: 0 | E16: 0 | F16: 0 | G16: 1 | H16: 0 | I16: 1 | J16: 1 | K16: 0 | L16: Não | N16: Mínimo | O16: 0.18 | P16: 0.01 | Q16: 0 | R16: 0.04 | S16: 0.34 | T16: 0.56 | U16: 140 | V16: 220
A17: Água | B17: 0 | C17: 0 | D17: 0 | E17: 0 | F17: 0 | G17: 0 | H17: 1 | I17: 0 | J17: 0 | K17: 0 | L17: Não | N17: Máximo | O17: 0.24 | P17: 0.1 | Q17: 0.01 | R17: 0.12 | S17: 0.44 | T17: 0.66 | U17: 260 | V17: 300
A18: Álcool 96° | B18: 22 | C18: 0 | D18: 0 | E18: 0 | F18: 0 | G18: 0 | H18: 1 | I18: 0 | J18: 3.5 | K18: 0 | L18: Não | N18: Base Vegana | O18: Açúcares | P18: Gorduras | Q18: SLNG | R18: OS | S18: ST | T18: Água | U18: POD | V18: PAC
A19: Ameixa Vermelha | B19: 0 | C19: 0.11 | D19: 0 | E19: 0 | F19: 0.02 | G19: 0.13 | H19: 0.87 | I19: 0.13 | J19: 0.15 | K19: 0.01 | L19: Não | N19: Mínimo | O19: 0.18 | P19: 0.08 | Q19: 0 | R19: 0.03 | S19: 0.35 | T19: 0.58 | U19: 129 | V19: 210
A20: Amendoim Torrado | B20: 22 | C20: 0.03 | D20: 0.5 | E20: 0 | F20: 0.44 | G20: 0.97 | H20: 0.03 | I20: 0.252 | J20: 0.3045 | K20: 0 | L20: Sim | N20: Máximo | O20: 0.24 | P20: 0.13 | Q20: 0.01 | R20: 0.15 | S20: 0.42 | T20: 0.65 | U20: 195 | V20: 300
A21: Amora | B21: 35 | C21: 0.08 | D21: 0 | E21: 0 | F21: 0.07 | G21: 0.15 | H21: 0.85 | I21: 0.095 | J21: 0.115 | K21: 0.01 | L21: Não | N21: Alcoólicos | O21: Açúcares | P21: Gorduras | Q21: SLNG | R21: OS | S21: ST | T21: Água | U21: POD | V21: PAC
A22: Atemoia | B22: 0 | C22: 0.21 | D22: 0.003 | E22: 0 | F22: 0.035 | G22: 0.248 | H22: 0.752 | I22: 0.22 | J22: 0.24 | K22: 0.019 | L22: Não | N22: Mínimo | O22: 0.16 | P22: 0.05 | Q22: 0.06 | R22: 0 | S22: 0.32 | T22: 0.54 | U22: 120 | V22: 250
A23: Banana | B23: 0 | C23: 0.16 | D23: 0 | E23: 0 | F23: 0.07 | G23: 0.23 | H23: 0.77 | I23: 0.19 | J23: 0.23 | K23: 0.01 | L23: Não | N23: Máximo | O23: 0.22 | P23: 0.16 | Q23: 0.12 | R23: 0.14 | S23: 0.46 | T23: 0.68 | U23: 210 | V23: 380
A24: Base de água | B24: {=IFERROR(SUMPRODUCT(('Pré-preparos e Variegatos'!$A$2:$A$1000=$A24)*'Pré-preparos e Variegatos'!$C$2:$C$1000*IFERROR(VLOOKUP('Pré-preparos e Variegatos'!$B$2:$B$1000, VSTACK($A$5:$K$23, $A$28:$K$31, $A$33:$K$58, $A$60:$K$96, $A$99:$K$137, $A$139:$K$140, $A$142:$K$151, $A$153:$K$168, $A$170:$K$188, $A$194:$K$500), 2, 0), 0))/SUMIF('Pré-preparos e Variegatos'!$A$2:$A$1000, $A24, 'Pré-preparos e Variegatos'!$C$2:$C$1000) * IFERROR(VLOOKUP($A24, 'Pré-preparos e Variegatos'!$M$2:$Q$100, 5, FALSE), 1), 0)} -> 9.8304743 | C24: {=IFERROR(SUMPRODUCT(('Pré-preparos e Variegatos'!$A$2:$A$1000=$A24)*'Pré-preparos e Variegatos'!$C$2:$C$1000*IFERROR(VLOOKUP('Pré-preparos e Variegatos'!$B$2:$B$1000, VSTACK($A$5:$K$23, $A$28:$K$31, $A$33:$K$58, $A$60:$K$96, $A$99:$K$137, $A$139:$K$140, $A$142:$K$151, $A$153:$K$168, $A$170:$K$188, $A$194:$K$500), 3, 0), 0))/SUMIF('Pré-preparos e Variegatos'!$A$2:$A$1000, $A24, 'Pré-preparos e Variegatos'!$C$2:$C$1000) * IFERROR(VLOOKUP($A24, 'Pré-preparos e Variegatos'!$M$2:$Q$100, 5, FALSE), 1), 0)} -> 0.47467205 | D24: {=IFERROR(SUMPRODUCT(('Pré-preparos e Variegatos'!$A$2:$A$1000=$A24)*'Pré-preparos e Variegatos'!$C$2:$C$1000*IFERROR(VLOOKUP('Pré-preparos e Variegatos'!$B$2:$B$1000, VSTACK($A$5:$K$23, $A$28:$K$31, $A$33:$K$58, $A$60:$K$96, $A$99:$K$137, $A$139:$K$140, $A$142:$K$151, $A$153:$K$168, $A$170:$K$188, $A$194:$K$500), 4, 0), 0))/SUMIF('Pré-preparos e Variegatos'!$A$2:$A$1000, $A24, 'Pré-preparos e Variegatos'!$C$2:$C$1000) * IFERROR(VLOOKUP($A24, 'Pré-preparos e Variegatos'!$M$2:$Q$100, 5, FALSE), 1), 0)} -> 0 | E24: {=IFERROR(SUMPRODUCT(('Pré-preparos e Variegatos'!$A$2:$A$1000=$A24)*'Pré-preparos e Variegatos'!$C$2:$C$1000*IFERROR(VLOOKUP('Pré-preparos e Variegatos'!$B$2:$B$1000, VSTACK($A$5:$K$23, $A$28:$K$31, $A$33:$K$58, $A$60:$K$96, $A$99:$K$137, $A$139:$K$140, $A$142:$K$151, $A$153:$K$168, $A$170:$K$188, $A$194:$K$500), 5, 0), 0))/SUMIF('Pré-preparos e Variegatos'!$A$2:$A$1000, $A24, 'Pré-preparos e Variegatos'!$C$2:$C$1000) * IFERROR(VLOOKUP($A24, 'Pré-preparos e Variegatos'!$M$2:$Q$100, 5, FALSE), 1), 0)} -> 0 | F24: {=IFERROR(SUMPRODUCT(('Pré-preparos e Variegatos'!$A$2:$A$1000=$A24)*'Pré-preparos e Variegatos'!$C$2:$C$1000*IFERROR(VLOOKUP('Pré-preparos e Variegatos'!$B$2:$B$1000, VSTACK($A$5:$K$23, $A$28:$K$31, $A$33:$K$58, $A$60:$K$96, $A$99:$K$137, $A$139:$K$140, $A$142:$K$151, $A$153:$K$168, $A$170:$K$188, $A$194:$K$500), 6, 0), 0))/SUMIF('Pré-preparos e Variegatos'!$A$2:$A$1000, $A24, 'Pré-preparos e Variegatos'!$C$2:$C$1000) * IFERROR(VLOOKUP($A24, 'Pré-preparos e Variegatos'!$M$2:$Q$100, 5, FALSE), 1), 0)} -> 0.016649849 | G24: =MIN(1, SUM(C24:F24)) -> 0.4913219 | H24: =1-G24 -> 0.5086781 | I24: {=IFERROR(SUMPRODUCT(('Pré-preparos e Variegatos'!$A$2:$A$1000=$A24)*'Pré-preparos e Variegatos'!$C$2:$C$1000*IFERROR(VLOOKUP('Pré-preparos e Variegatos'!$B$2:$B$1000, VSTACK($A$5:$K$23, $A$28:$K$31, $A$33:$K$58, $A$60:$K$96, $A$99:$K$137, $A$139:$K$140, $A$142:$K$151, $A$153:$K$168, $A$170:$K$188, $A$194:$K$500), 9, 0), 0))/SUMIF('Pré-preparos e Variegatos'!$A$2:$A$1000, $A24, 'Pré-preparos e Variegatos'!$C$2:$C$1000) * IFERROR(VLOOKUP($A24, 'Pré-preparos e Variegatos'!$M$2:$Q$100, 5, FALSE), 1), 0)} -> 0.42421796 | J24: {=IFERROR(SUMPRODUCT(('Pré-preparos e Variegatos'!$A$2:$A$1000=$A24)*'Pré-preparos e Variegatos'!$C$2:$C$1000*IFERROR(VLOOKUP('Pré-preparos e Variegatos'!$B$2:$B$1000, VSTACK($A$5:$K$23, $A$28:$K$31, $A$33:$K$58, $A$60:$K$96, $A$99:$K$137, $A$139:$K$140, $A$142:$K$151, $A$153:$K$168, $A$170:$K$188, $A$194:$K$500), 10, 0), 0))/SUMIF('Pré-preparos e Variegatos'!$A$2:$A$1000, $A24, 'Pré-preparos e Variegatos'!$C$2:$C$1000) * IFERROR(VLOOKUP($A24, 'Pré-preparos e Variegatos'!$M$2:$Q$100, 5, FALSE), 1), 0)} -> 0.53562059 | K24: {=IFERROR(SUMPRODUCT(('Pré-preparos e Variegatos'!$A$2:$A$1000=$A24)*'Pré-preparos e Variegatos'!$C$2:$C$1000*IFERROR(VLOOKUP('Pré-preparos e Variegatos'!$B$2:$B$1000, VSTACK($A$5:$K$23, $A$28:$K$31, $A$33:$K$58, $A$60:$K$96, $A$99:$K$137, $A$139:$K$140, $A$142:$K$151, $A$153:$K$168, $A$170:$K$188, $A$194:$K$500), 11, 0), 0))/SUMIF('Pré-preparos e Variegatos'!$A$2:$A$1000, $A24, 'Pré-preparos e Variegatos'!$C$2:$C$1000) * IFERROR(VLOOKUP($A24, 'Pré-preparos e Variegatos'!$M$2:$Q$100, 5, FALSE), 1), 0)} -> 0 | L24: {=IF(SUMPRODUCT(('Pré-preparos e Variegatos'!$A$2:$A$1000=$A24)*(IFERROR(VLOOKUP('Pré-preparos e Variegatos'!$B$2:$B$1000, VSTACK($A$5:$L$23, $A$28:$L$31, $A$33:$L$58, $A$60:$L$96, $A$99:$L$137, $A$139:$L$140, $A$142:$L$151, $A$153:$L$168, $A$170:$L$188, $A$194:$L$500), 12, 0), "Não")="Sim"))>0, "Sim", "Não")} -> Não | N24: Zero | O24: Açúcares | P24: Gorduras | Q24: SLNG | R24: OS | S24: ST | T24: Água | U24: POD | V24: PAC
A25: Base de leite | B25: {=IFERROR(SUMPRODUCT(('Pré-preparos e Variegatos'!$A$2:$A$1000=$A25)*'Pré-preparos e Variegatos'!$C$2:$C$1000*IFERROR(VLOOKUP('Pré-preparos e Variegatos'!$B$2:$B$1000, VSTACK($A$5:$K$23, $A$28:$K$31, $A$33:$K$58, $A$60:$K$96, $A$99:$K$137, $A$139:$K$140, $A$142:$K$151, $A$153:$K$168, $A$170:$K$188, $A$194:$K$500), 2, 0), 0))/SUMIF('Pré-preparos e Variegatos'!$A$2:$A$1000, $A25, 'Pré-preparos e Variegatos'!$C$2:$C$1000) * IFERROR(VLOOKUP($A25, 'Pré-preparos e Variegatos'!$M$2:$Q$100, 5, FALSE), 1), 0)} -> 14.838323 | C25: {=IFERROR(SUMPRODUCT(('Pré-preparos e Variegatos'!$A$2:$A$1000=$A25)*'Pré-preparos e Variegatos'!$C$2:$C$1000*IFERROR(VLOOKUP('Pré-preparos e Variegatos'!$B$2:$B$1000, VSTACK($A$5:$K$23, $A$28:$K$31, $A$33:$K$58, $A$60:$K$96, $A$99:$K$137, $A$139:$K$140, $A$142:$K$151, $A$153:$K$168, $A$170:$K$188, $A$194:$K$500), 3, 0), 0))/SUMIF('Pré-preparos e Variegatos'!$A$2:$A$1000, $A25, 'Pré-preparos e Variegatos'!$C$2:$C$1000) * IFERROR(VLOOKUP($A25, 'Pré-preparos e Variegatos'!$M$2:$Q$100, 5, FALSE), 1), 0)} -> 0.17035928 | D25: {=IFERROR(SUMPRODUCT(('Pré-preparos e Variegatos'!$A$2:$A$1000=$A25)*'Pré-preparos e Variegatos'!$C$2:$C$1000*IFERROR(VLOOKUP('Pré-preparos e Variegatos'!$B$2:$B$1000, VSTACK($A$5:$K$23, $A$28:$K$31, $A$33:$K$58, $A$60:$K$96, $A$99:$K$137, $A$139:$K$140, $A$142:$K$151, $A$153:$K$168, $A$170:$K$188, $A$194:$K$500), 4, 0), 0))/SUMIF('Pré-preparos e Variegatos'!$A$2:$A$1000, $A25, 'Pré-preparos e Variegatos'!$C$2:$C$1000) * IFERROR(VLOOKUP($A25, 'Pré-preparos e Variegatos'!$M$2:$Q$100, 5, FALSE), 1), 0)} -> 0.077894212 | E25: {=IFERROR(SUMPRODUCT(('Pré-preparos e Variegatos'!$A$2:$A$1000=$A25)*'Pré-preparos e Variegatos'!$C$2:$C$1000*IFERROR(VLOOKUP('Pré-preparos e Variegatos'!$B$2:$B$1000, VSTACK($A$5:$K$23, $A$28:$K$31, $A$33:$K$58, $A$60:$K$96, $A$99:$K$137, $A$139:$K$140, $A$142:$K$151, $A$153:$K$168, $A$170:$K$188, $A$194:$K$500), 5, 0), 0))/SUMIF('Pré-preparos e Variegatos'!$A$2:$A$1000, $A25, 'Pré-preparos e Variegatos'!$C$2:$C$1000) * IFERROR(VLOOKUP($A25, 'Pré-preparos e Variegatos'!$M$2:$Q$100, 5, FALSE), 1), 0)} -> 0.10553892 | F25: {=IFERROR(SUMPRODUCT(('Pré-preparos e Variegatos'!$A$2:$A$1000=$A25)*'Pré-preparos e Variegatos'!$C$2:$C$1000*IFERROR(VLOOKUP('Pré-preparos e Variegatos'!$B$2:$B$1000, VSTACK($A$5:$K$23, $A$28:$K$31, $A$33:$K$58, $A$60:$K$96, $A$99:$K$137, $A$139:$K$140, $A$142:$K$151, $A$153:$K$168, $A$170:$K$188, $A$194:$K$500), 6, 0), 0))/SUMIF('Pré-preparos e Variegatos'!$A$2:$A$1000, $A25, 'Pré-preparos e Variegatos'!$C$2:$C$1000) * IFERROR(VLOOKUP($A25, 'Pré-preparos e Variegatos'!$M$2:$Q$100, 5, FALSE), 1), 0)} -> 0.035279441 | G25: =MIN(1, SUM(C25:F25)) -> 0.38907186 | H25: =1-G25 -> 0.61092814 | I25: {=IFERROR(SUMPRODUCT(('Pré-preparos e Variegatos'!$A$2:$A$1000=$A25)*'Pré-preparos e Variegatos'!$C$2:$C$1000*IFERROR(VLOOKUP('Pré-preparos e Variegatos'!$B$2:$B$1000, VSTACK($A$5:$K$23, $A$28:$K$31, $A$33:$K$58, $A$60:$K$96, $A$99:$K$137, $A$139:$K$140, $A$142:$K$151, $A$153:$K$168, $A$170:$K$188, $A$194:$K$500), 9, 0), 0))/SUMIF('Pré-preparos e Variegatos'!$A$2:$A$1000, $A25, 'Pré-preparos e Variegatos'!$C$2:$C$1000) * IFERROR(VLOOKUP($A25, 'Pré-preparos e Variegatos'!$M$2:$Q$100, 5, FALSE), 1), 0)} -> 0.1566018 | J25: {=IFERROR(SUMPRODUCT(('Pré-preparos e Variegatos'!$A$2:$A$1000=$A25)*'Pré-preparos e Variegatos'!$C$2:$C$1000*IFERROR(VLOOKUP('Pré-preparos e Variegatos'!$B$2:$B$1000, VSTACK($A$5:$K$23, $A$28:$K$31, $A$33:$K$58, $A$60:$K$96, $A$99:$K$137, $A$139:$K$140, $A$142:$K$151, $A$153:$K$168, $A$170:$K$188, $A$194:$K$500), 10, 0), 0))/SUMIF('Pré-preparos e Variegatos'!$A$2:$A$1000, $A25, 'Pré-preparos e Variegatos'!$C$2:$C$1000) * IFERROR(VLOOKUP($A25, 'Pré-preparos e Variegatos'!$M$2:$Q$100, 5, FALSE), 1), 0)} -> 0.2507485 | K25: {=IFERROR(SUMPRODUCT(('Pré-preparos e Variegatos'!$A$2:$A$1000=$A25)*'Pré-preparos e Variegatos'!$C$2:$C$1000*IFERROR(VLOOKUP('Pré-preparos e Variegatos'!$B$2:$B$1000, VSTACK($A$5:$K$23, $A$28:$K$31, $A$33:$K$58, $A$60:$K$96, $A$99:$K$137, $A$139:$K$140, $A$142:$K$151, $A$153:$K$168, $A$170:$K$188, $A$194:$K$500), 11, 0), 0))/SUMIF('Pré-preparos e Variegatos'!$A$2:$A$1000, $A25, 'Pré-preparos e Variegatos'!$C$2:$C$1000) * IFERROR(VLOOKUP($A25, 'Pré-preparos e Variegatos'!$M$2:$Q$100, 5, FALSE), 1), 0)} -> 0.040379242 | L25: {=IF(SUMPRODUCT(('Pré-preparos e Variegatos'!$A$2:$A$1000=$A25)*(IFERROR(VLOOKUP('Pré-preparos e Variegatos'!$B$2:$B$1000, VSTACK($A$5:$L$23, $A$28:$L$31, $A$33:$L$58, $A$60:$L$96, $A$99:$L$137, $A$139:$L$140, $A$142:$L$151, $A$153:$L$168, $A$170:$L$188, $A$194:$L$500), 12, 0), "Não")="Sim"))>0, "Sim", "Não")} -> Sim | N25: Mínimo | O25: 0.04 | P25: 0 | Q25: 0 | R25: 0.01 | S25: 0.28 | T25: 0.58 | U25: 95 | V25: 220
A26: Base de Leite (Creme de leite 17% UHT) | B26: {=IFERROR(SUMPRODUCT(('Pré-preparos e Variegatos'!$A$2:$A$1000=$A26)*'Pré-preparos e Variegatos'!$C$2:$C$1000*IFERROR(VLOOKUP('Pré-preparos e Variegatos'!$B$2:$B$1000, VSTACK($A$5:$K$23, $A$28:$K$31, $A$33:$K$58, $A$60:$K$96, $A$99:$K$137, $A$139:$K$140, $A$142:$K$151, $A$153:$K$168, $A$170:$K$188, $A$194:$K$500), 2, 0), 0))/SUMIF('Pré-preparos e Variegatos'!$A$2:$A$1000, $A26, 'Pré-preparos e Variegatos'!$C$2:$C$1000) * IFERROR(VLOOKUP($A26, 'Pré-preparos e Variegatos'!$M$2:$Q$100, 5, FALSE), 1), 0)} -> 15.1429 | C26: {=IFERROR(SUMPRODUCT(('Pré-preparos e Variegatos'!$A$2:$A$1000=$A26)*'Pré-preparos e Variegatos'!$C$2:$C$1000*IFERROR(VLOOKUP('Pré-preparos e Variegatos'!$B$2:$B$1000, VSTACK($A$5:$K$23, $A$28:$K$31, $A$33:$K$58, $A$60:$K$96, $A$99:$K$137, $A$139:$K$140, $A$142:$K$151, $A$153:$K$168, $A$170:$K$188, $A$194:$K$500), 3, 0), 0))/SUMIF('Pré-preparos e Variegatos'!$A$2:$A$1000, $A26, 'Pré-preparos e Variegatos'!$C$2:$C$1000) * IFERROR(VLOOKUP($A26, 'Pré-preparos e Variegatos'!$M$2:$Q$100, 5, FALSE), 1), 0)} -> 0.17135 | D26: {=IFERROR(SUMPRODUCT(('Pré-preparos e Variegatos'!$A$2:$A$1000=$A26)*'Pré-preparos e Variegatos'!$C$2:$C$1000*IFERROR(VLOOKUP('Pré-preparos e Variegatos'!$B$2:$B$1000, VSTACK($A$5:$K$23, $A$28:$K$31, $A$33:$K$58, $A$60:$K$96, $A$99:$K$137, $A$139:$K$140, $A$142:$K$151, $A$153:$K$168, $A$170:$K$188, $A$194:$K$500), 4, 0), 0))/SUMIF('Pré-preparos e Variegatos'!$A$2:$A$1000, $A26, 'Pré-preparos e Variegatos'!$C$2:$C$1000) * IFERROR(VLOOKUP($A26, 'Pré-preparos e Variegatos'!$M$2:$Q$100, 5, FALSE), 1), 0)} -> 0.057915 | E26: {=IFERROR(SUMPRODUCT(('Pré-preparos e Variegatos'!$A$2:$A$1000=$A26)*'Pré-preparos e Variegatos'!$C$2:$C$1000*IFERROR(VLOOKUP('Pré-preparos e Variegatos'!$B$2:$B$1000, VSTACK($A$5:$K$23, $A$28:$K$31, $A$33:$K$58, $A$60:$K$96, $A$99:$K$137, $A$139:$K$140, $A$142:$K$151, $A$153:$K$168, $A$170:$K$188, $A$194:$K$500), 5, 0), 0))/SUMIF('Pré-preparos e Variegatos'!$A$2:$A$1000, $A26, 'Pré-preparos e Variegatos'!$C$2:$C$1000) * IFERROR(VLOOKUP($A26, 'Pré-preparos e Variegatos'!$M$2:$Q$100, 5, FALSE), 1), 0)} -> 0.10931 | F26: {=IFERROR(SUMPRODUCT(('Pré-preparos e Variegatos'!$A$2:$A$1000=$A26)*'Pré-preparos e Variegatos'!$C$2:$C$1000*IFERROR(VLOOKUP('Pré-preparos e Variegatos'!$B$2:$B$1000, VSTACK($A$5:$K$23, $A$28:$K$31, $A$33:$K$58, $A$60:$K$96, $A$99:$K$137, $A$139:$K$140, $A$142:$K$151, $A$153:$K$168, $A$170:$K$188, $A$194:$K$500), 6, 0), 0))/SUMIF('Pré-preparos e Variegatos'!$A$2:$A$1000, $A26, 'Pré-preparos e Variegatos'!$C$2:$C$1000) * IFERROR(VLOOKUP($A26, 'Pré-preparos e Variegatos'!$M$2:$Q$100, 5, FALSE), 1), 0)} -> 0.044 | G26: =MIN(1, SUM(C26:F26)) -> 0.382575 | H26: =1-G26 -> 0.617425 | I26: {=IFERROR(SUMPRODUCT(('Pré-preparos e Variegatos'!$A$2:$A$1000=$A26)*'Pré-preparos e Variegatos'!$C$2:$C$1000*IFERROR(VLOOKUP('Pré-preparos e Variegatos'!$B$2:$B$1000, VSTACK($A$5:$K$23, $A$28:$K$31, $A$33:$K$58, $A$60:$K$96, $A$99:$K$137, $A$139:$K$140, $A$142:$K$151, $A$153:$K$168, $A$170:$K$188, $A$194:$K$500), 9, 0), 0))/SUMIF('Pré-preparos e Variegatos'!$A$2:$A$1000, $A26, 'Pré-preparos e Variegatos'!$C$2:$C$1000) * IFERROR(VLOOKUP($A26, 'Pré-preparos e Variegatos'!$M$2:$Q$100, 5, FALSE), 1), 0)} -> 0.1613102 | J26: {=IFERROR(SUMPRODUCT(('Pré-preparos e Variegatos'!$A$2:$A$1000=$A26)*'Pré-preparos e Variegatos'!$C$2:$C$1000*IFERROR(VLOOKUP('Pré-preparos e Variegatos'!$B$2:$B$1000, VSTACK($A$5:$K$23, $A$28:$K$31, $A$33:$K$58, $A$60:$K$96, $A$99:$K$137, $A$139:$K$140, $A$142:$K$151, $A$153:$K$168, $A$170:$K$188, $A$194:$K$500), 10, 0), 0))/SUMIF('Pré-preparos e Variegatos'!$A$2:$A$1000, $A26, 'Pré-preparos e Variegatos'!$C$2:$C$1000) * IFERROR(VLOOKUP($A26, 'Pré-preparos e Variegatos'!$M$2:$Q$100, 5, FALSE), 1), 0)} -> 0.25426 | K26: {=IFERROR(SUMPRODUCT(('Pré-preparos e Variegatos'!$A$2:$A$1000=$A26)*'Pré-preparos e Variegatos'!$C$2:$C$1000*IFERROR(VLOOKUP('Pré-preparos e Variegatos'!$B$2:$B$1000, VSTACK($A$5:$K$23, $A$28:$K$31, $A$33:$K$58, $A$60:$K$96, $A$99:$K$137, $A$139:$K$140, $A$142:$K$151, $A$153:$K$168, $A$170:$K$188, $A$194:$K$500), 11, 0), 0))/SUMIF('Pré-preparos e Variegatos'!$A$2:$A$1000, $A26, 'Pré-preparos e Variegatos'!$C$2:$C$1000) * IFERROR(VLOOKUP($A26, 'Pré-preparos e Variegatos'!$M$2:$Q$100, 5, FALSE), 1), 0)} -> 0.040875 | L26: {=IF(SUMPRODUCT(('Pré-preparos e Variegatos'!$A$2:$A$1000=$A26)*(IFERROR(VLOOKUP('Pré-preparos e Variegatos'!$B$2:$B$1000, VSTACK($A$5:$L$23, $A$28:$L$31, $A$33:$L$58, $A$60:$L$96, $A$99:$L$137, $A$139:$L$140, $A$142:$L$151, $A$153:$L$168, $A$170:$L$188, $A$194:$L$500), 12, 0), "Não")="Sim"))>0, "Sim", "Não")} -> Sim | N26: Máximo | O26: 0.28 | P26: 0.12 | Q26: 0.13 | R26: 0.23 | S26: 0.42 | T26: 0.72 | U26: 305 | V26: 395
A27: Base de leite(Fior di latte) | B27: {=IFERROR(SUMPRODUCT(('Pré-preparos e Variegatos'!$A$2:$A$1000=$A27)*'Pré-preparos e Variegatos'!$C$2:$C$1000*IFERROR(VLOOKUP('Pré-preparos e Variegatos'!$B$2:$B$1000, VSTACK($A$5:$K$23, $A$28:$K$31, $A$33:$K$58, $A$60:$K$96, $A$99:$K$137, $A$139:$K$140, $A$142:$K$151, $A$153:$K$168, $A$170:$K$188, $A$194:$K$500), 2, 0), 0))/SUMIF('Pré-preparos e Variegatos'!$A$2:$A$1000, $A27, 'Pré-preparos e Variegatos'!$C$2:$C$1000) * IFERROR(VLOOKUP($A27, 'Pré-preparos e Variegatos'!$M$2:$Q$100, 5, FALSE), 1), 0)} -> 11.703796 | C27: {=IFERROR(SUMPRODUCT(('Pré-preparos e Variegatos'!$A$2:$A$1000=$A27)*'Pré-preparos e Variegatos'!$C$2:$C$1000*IFERROR(VLOOKUP('Pré-preparos e Variegatos'!$B$2:$B$1000, VSTACK($A$5:$K$23, $A$28:$K$31, $A$33:$K$58, $A$60:$K$96, $A$99:$K$137, $A$139:$K$140, $A$142:$K$151, $A$153:$K$168, $A$170:$K$188, $A$194:$K$500), 3, 0), 0))/SUMIF('Pré-preparos e Variegatos'!$A$2:$A$1000, $A27, 'Pré-preparos e Variegatos'!$C$2:$C$1000) * IFERROR(VLOOKUP($A27, 'Pré-preparos e Variegatos'!$M$2:$Q$100, 5, FALSE), 1), 0)} -> 0.17592408 | D27: {=IFERROR(SUMPRODUCT(('Pré-preparos e Variegatos'!$A$2:$A$1000=$A27)*'Pré-preparos e Variegatos'!$C$2:$C$1000*IFERROR(VLOOKUP('Pré-preparos e Variegatos'!$B$2:$B$1000, VSTACK($A$5:$K$23, $A$28:$K$31, $A$33:$K$58, $A$60:$K$96, $A$99:$K$137, $A$139:$K$140, $A$142:$K$151, $A$153:$K$168, $A$170:$K$188, $A$194:$K$500), 4, 0), 0))/SUMIF('Pré-preparos e Variegatos'!$A$2:$A$1000, $A27, 'Pré-preparos e Variegatos'!$C$2:$C$1000) * IFERROR(VLOOKUP($A27, 'Pré-preparos e Variegatos'!$M$2:$Q$100, 5, FALSE), 1), 0)} -> 0.074125874 | E27: {=IFERROR(SUMPRODUCT(('Pré-preparos e Variegatos'!$A$2:$A$1000=$A27)*'Pré-preparos e Variegatos'!$C$2:$C$1000*IFERROR(VLOOKUP('Pré-preparos e Variegatos'!$B$2:$B$1000, VSTACK($A$5:$K$23, $A$28:$K$31, $A$33:$K$58, $A$60:$K$96, $A$99:$K$137, $A$139:$K$140, $A$142:$K$151, $A$153:$K$168, $A$170:$K$188, $A$194:$K$500), 5, 0), 0))/SUMIF('Pré-preparos e Variegatos'!$A$2:$A$1000, $A27, 'Pré-preparos e Variegatos'!$C$2:$C$1000) * IFERROR(VLOOKUP($A27, 'Pré-preparos e Variegatos'!$M$2:$Q$100, 5, FALSE), 1), 0)} -> 0.10834166 | F27: {=IFERROR(SUMPRODUCT(('Pré-preparos e Variegatos'!$A$2:$A$1000=$A27)*'Pré-preparos e Variegatos'!$C$2:$C$1000*IFERROR(VLOOKUP('Pré-preparos e Variegatos'!$B$2:$B$1000, VSTACK($A$5:$K$23, $A$28:$K$31, $A$33:$K$58, $A$60:$K$96, $A$99:$K$137, $A$139:$K$140, $A$142:$K$151, $A$153:$K$168, $A$170:$K$188, $A$194:$K$500), 6, 0), 0))/SUMIF('Pré-preparos e Variegatos'!$A$2:$A$1000, $A27, 'Pré-preparos e Variegatos'!$C$2:$C$1000) * IFERROR(VLOOKUP($A27, 'Pré-preparos e Variegatos'!$M$2:$Q$100, 5, FALSE), 1), 0)} -> 0.005994006 | G27: =MIN(1, SUM(C27:F27)) -> 0.36438561 | H27: =1-G27 -> 0.63561439 | I27: {=IFERROR(SUMPRODUCT(('Pré-preparos e Variegatos'!$A$2:$A$1000=$A27)*'Pré-preparos e Variegatos'!$C$2:$C$1000*IFERROR(VLOOKUP('Pré-preparos e Variegatos'!$B$2:$B$1000, VSTACK($A$5:$K$23, $A$28:$K$31, $A$33:$K$58, $A$60:$K$96, $A$99:$K$137, $A$139:$K$140, $A$142:$K$151, $A$153:$K$168, $A$170:$K$188, $A$194:$K$500), 9, 0), 0))/SUMIF('Pré-preparos e Variegatos'!$A$2:$A$1000, $A27, 'Pré-preparos e Variegatos'!$C$2:$C$1000) * IFERROR(VLOOKUP($A27, 'Pré-preparos e Variegatos'!$M$2:$Q$100, 5, FALSE), 1), 0)} -> 0.16328272 | J27: {=IFERROR(SUMPRODUCT(('Pré-preparos e Variegatos'!$A$2:$A$1000=$A27)*'Pré-preparos e Variegatos'!$C$2:$C$1000*IFERROR(VLOOKUP('Pré-preparos e Variegatos'!$B$2:$B$1000, VSTACK($A$5:$K$23, $A$28:$K$31, $A$33:$K$58, $A$60:$K$96, $A$99:$K$137, $A$139:$K$140, $A$142:$K$151, $A$153:$K$168, $A$170:$K$188, $A$194:$K$500), 10, 0), 0))/SUMIF('Pré-preparos e Variegatos'!$A$2:$A$1000, $A27, 'Pré-preparos e Variegatos'!$C$2:$C$1000) * IFERROR(VLOOKUP($A27, 'Pré-preparos e Variegatos'!$M$2:$Q$100, 5, FALSE), 1), 0)} -> 0.24955045 | K27: {=IFERROR(SUMPRODUCT(('Pré-preparos e Variegatos'!$A$2:$A$1000=$A27)*'Pré-preparos e Variegatos'!$C$2:$C$1000*IFERROR(VLOOKUP('Pré-preparos e Variegatos'!$B$2:$B$1000, VSTACK($A$5:$K$23, $A$28:$K$31, $A$33:$K$58, $A$60:$K$96, $A$99:$K$137, $A$139:$K$140, $A$142:$K$151, $A$153:$K$168, $A$170:$K$188, $A$194:$K$500), 11, 0), 0))/SUMIF('Pré-preparos e Variegatos'!$A$2:$A$1000, $A27, 'Pré-preparos e Variegatos'!$C$2:$C$1000) * IFERROR(VLOOKUP($A27, 'Pré-preparos e Variegatos'!$M$2:$Q$100, 5, FALSE), 1), 0)} -> 0.041458541 | L27: {=IF(SUMPRODUCT(('Pré-preparos e Variegatos'!$A$2:$A$1000=$A27)*(IFERROR(VLOOKUP('Pré-preparos e Variegatos'!$B$2:$B$1000, VSTACK($A$5:$L$23, $A$28:$L$31, $A$33:$L$58, $A$60:$L$96, $A$99:$L$137, $A$139:$L$140, $A$142:$L$151, $A$153:$L$168, $A$170:$L$188, $A$194:$L$500), 12, 0), "Não")="Sim"))>0, "Sim", "Não")} -> Sim | N27: Gelatos Proteicos | O27: Açúcares | P27: Gorduras | Q27: SLNG | R27: OS | S27: ST | T27: Água | U27: POD | V27: PAC | W27: Proteína
A28: Batata doce roxa | B28: 0 | C28: 0.04 | D28: 0.0005 | E28: 0 | F28: =17.4/100 -> 0.174 | G28: =SUM(C28:F28) -> 0.2145 | H28: =1-G28 -> 0.7855 | I28: =C28*1 -> 0.04 | J28: =C28*1 -> 0.04 | K28: 0.016 | L28: Não | N28: Mínimo | O28: 0.05 | P28: 0.04 | Q28: 0.12 | R28: 0 | S28: 0.35 | T28: 0.57 | U28: 110 | V28: 220 | W28: 0.08
A29: Biscoff | B29: 175 | C29: 0.37 | D29: 0.38 | E29: 0 | F29: 0.17 | G29: =SUM(C29:F29) -> 0.92 | H29: =1-G29 -> 0.08 | I29: 0.37 | J29: 0.37 | K29: 0.029 | L29: Sim | N29: Máximo | O29: 0.21 | P29: 0.06 | Q29: 0.17 | R29: 0.14 | S29: 0.43 | T29: 0.65 | U29: 220 | V29: 340 | W29: 0.1
A30: Biscoito Champanhe | B30: 32 | C30: 0.26 | D30: 0.09 | E30: 0 | F30: 0.45 | G30: 0.8 | H30: 0.2 | I30: 0.25 | J30: 0.25 | K30: 0.106 | L30: Sim
A31: Biscoito Chocolate | B31: 38 | C31: 0.24 | D31: 0.078 | E31: 0.035 | F31: 0.647 | G31: 1 | H31: 0 | I31: 0 | J31: 0 | K31: 0.073 | L31: Sim | N31: Redução de Açúcar | O31: Açúcares | P31: Gorduras | Q31: SLNG | R31: OS | S31: ST | T31: Água | U31: POD | V31: PAC
A32: Brigadeiro | B32: {=IFERROR(SUMPRODUCT(('Pré-preparos e Variegatos'!$A$2:$A$1000=$A32)*'Pré-preparos e Variegatos'!$C$2:$C$1000*IFERROR(VLOOKUP('Pré-preparos e Variegatos'!$B$2:$B$1000, VSTACK($A$5:$K$23, $A$28:$K$31, $A$33:$K$58, $A$60:$K$96, $A$99:$K$137, $A$139:$K$140, $A$142:$K$151, $A$153:$K$168, $A$170:$K$188, $A$194:$K$500), 2, 0), 0))/SUMIF('Pré-preparos e Variegatos'!$A$2:$A$1000, $A32, 'Pré-preparos e Variegatos'!$C$2:$C$1000) * IFERROR(VLOOKUP($A32, 'Pré-preparos e Variegatos'!$M$2:$Q$100, 5, FALSE), 1), 0)} -> 46.592033 | C32: {=IFERROR(SUMPRODUCT(('Pré-preparos e Variegatos'!$A$2:$A$1000=$A32)*'Pré-preparos e Variegatos'!$C$2:$C$1000*IFERROR(VLOOKUP('Pré-preparos e Variegatos'!$B$2:$B$1000, VSTACK($A$5:$K$23, $A$28:$K$31, $A$33:$K$58, $A$60:$K$96, $A$99:$K$137, $A$139:$K$140, $A$142:$K$151, $A$153:$K$168, $A$170:$K$188, $A$194:$K$500), 3, 0), 0))/SUMIF('Pré-preparos e Variegatos'!$A$2:$A$1000, $A32, 'Pré-preparos e Variegatos'!$C$2:$C$1000) * IFERROR(VLOOKUP($A32, 'Pré-preparos e Variegatos'!$M$2:$Q$100, 5, FALSE), 1), 0)} -> 0.27010989 | D32: {=IFERROR(SUMPRODUCT(('Pré-preparos e Variegatos'!$A$2:$A$1000=$A32)*'Pré-preparos e Variegatos'!$C$2:$C$1000*IFERROR(VLOOKUP('Pré-preparos e Variegatos'!$B$2:$B$1000, VSTACK($A$5:$K$23, $A$28:$K$31, $A$33:$K$58, $A$60:$K$96, $A$99:$K$137, $A$139:$K$140, $A$142:$K$151, $A$153:$K$168, $A$170:$K$188, $A$194:$K$500), 4, 0), 0))/SUMIF('Pré-preparos e Variegatos'!$A$2:$A$1000, $A32, 'Pré-preparos e Variegatos'!$C$2:$C$1000) * IFERROR(VLOOKUP($A32, 'Pré-preparos e Variegatos'!$M$2:$Q$100, 5, FALSE), 1), 0)} -> 0.15296703 | E32: {=IFERROR(SUMPRODUCT(('Pré-preparos e Variegatos'!$A$2:$A$1000=$A32)*'Pré-preparos e Variegatos'!$C$2:$C$1000*IFERROR(VLOOKUP('Pré-preparos e Variegatos'!$B$2:$B$1000, VSTACK($A$5:$K$23, $A$28:$K$31, $A$33:$K$58, $A$60:$K$96, $A$99:$K$137, $A$139:$K$140, $A$142:$K$151, $A$153:$K$168, $A$170:$K$188, $A$194:$K$500), 5, 0), 0))/SUMIF('Pré-preparos e Variegatos'!$A$2:$A$1000, $A32, 'Pré-preparos e Variegatos'!$C$2:$C$1000) * IFERROR(VLOOKUP($A32, 'Pré-preparos e Variegatos'!$M$2:$Q$100, 5, FALSE), 1), 0)} -> 0.11416484 | F32: {=IFERROR(SUMPRODUCT(('Pré-preparos e Variegatos'!$A$2:$A$1000=$A32)*'Pré-preparos e Variegatos'!$C$2:$C$1000*IFERROR(VLOOKUP('Pré-preparos e Variegatos'!$B$2:$B$1000, VSTACK($A$5:$K$23, $A$28:$K$31, $A$33:$K$58, $A$60:$K$96, $A$99:$K$137, $A$139:$K$140, $A$142:$K$151, $A$153:$K$168, $A$170:$K$188, $A$194:$K$500), 6, 0), 0))/SUMIF('Pré-preparos e Variegatos'!$A$2:$A$1000, $A32, 'Pré-preparos e Variegatos'!$C$2:$C$1000) * IFERROR(VLOOKUP($A32, 'Pré-preparos e Variegatos'!$M$2:$Q$100, 5, FALSE), 1), 0)} -> 0.019241758 | G32: =MIN(1, SUM(C32:F32)) -> 0.55648352 | H32: =1-G32 -> 0.44351648 | I32: {=IFERROR(SUMPRODUCT(('Pré-preparos e Variegatos'!$A$2:$A$1000=$A32)*'Pré-preparos e Variegatos'!$C$2:$C$1000*IFERROR(VLOOKUP('Pré-preparos e Variegatos'!$B$2:$B$1000, VSTACK($A$5:$K$23, $A$28:$K$31, $A$33:$K$58, $A$60:$K$96, $A$99:$K$137, $A$139:$K$140, $A$142:$K$151, $A$153:$K$168, $A$170:$K$188, $A$194:$K$500), 9, 0), 0))/SUMIF('Pré-preparos e Variegatos'!$A$2:$A$1000, $A32, 'Pré-preparos e Variegatos'!$C$2:$C$1000) * IFERROR(VLOOKUP($A32, 'Pré-preparos e Variegatos'!$M$2:$Q$100, 5, FALSE), 1), 0)} -> 0.29508791 | J32: {=IFERROR(SUMPRODUCT(('Pré-preparos e Variegatos'!$A$2:$A$1000=$A32)*'Pré-preparos e Variegatos'!$C$2:$C$1000*IFERROR(VLOOKUP('Pré-preparos e Variegatos'!$B$2:$B$1000, VSTACK($A$5:$K$23, $A$28:$K$31, $A$33:$K$58, $A$60:$K$96, $A$99:$K$137, $A$139:$K$140, $A$142:$K$151, $A$153:$K$168, $A$170:$K$188, $A$194:$K$500), 10, 0), 0))/SUMIF('Pré-preparos e Variegatos'!$A$2:$A$1000, $A32, 'Pré-preparos e Variegatos'!$C$2:$C$1000) * IFERROR(VLOOKUP($A32, 'Pré-preparos e Variegatos'!$M$2:$Q$100, 5, FALSE), 1), 0)} -> 0.335 | K32: {=IFERROR(SUMPRODUCT(('Pré-preparos e Variegatos'!$A$2:$A$1000=$A32)*'Pré-preparos e Variegatos'!$C$2:$C$1000*IFERROR(VLOOKUP('Pré-preparos e Variegatos'!$B$2:$B$1000, VSTACK($A$5:$K$23, $A$28:$K$31, $A$33:$K$58, $A$60:$K$96, $A$99:$K$137, $A$139:$K$140, $A$142:$K$151, $A$153:$K$168, $A$170:$K$188, $A$194:$K$500), 11, 0), 0))/SUMIF('Pré-preparos e Variegatos'!$A$2:$A$1000, $A32, 'Pré-preparos e Variegatos'!$C$2:$C$1000) * IFERROR(VLOOKUP($A32, 'Pré-preparos e Variegatos'!$M$2:$Q$100, 5, FALSE), 1), 0)} -> 0.055824176 | L32: {=IF(SUMPRODUCT(('Pré-preparos e Variegatos'!$A$2:$A$1000=$A32)*(IFERROR(VLOOKUP('Pré-preparos e Variegatos'!$B$2:$B$1000, VSTACK($A$5:$L$23, $A$28:$L$31, $A$33:$L$58, $A$60:$L$96, $A$99:$L$137, $A$139:$L$140, $A$142:$L$151, $A$153:$L$168, $A$170:$L$188, $A$194:$L$500), 12, 0), "Não")="Sim"))>0, "Sim", "Não")} -> Sim | N32: Mínimo | O32: 0.08 | P32: 0 | Q32: 0 | R32: 0 | S32: 0.3 | T32: 0.58 | U32: 110 | V32: 210
A33: Cacau Em Pó 11% gordura | B33: 42 | C33: 0 | D33: 0.11 | E33: 0 | F33: 0.84 | G33: 0.95 | H33: 0.05 | I33: 0 | J33: 0 | K33: 0.18 | L33: Não | N33: Máximo | O33: 0.18 | P33: 0.12 | Q33: 0.12 | R33: 0.16 | S33: 0.42 | T33: 0.7 | U33: 190 | V33: 300
A34: Cacau Em Pó 22% gordura | B34: 215 | C34: 0 | D34: 0.22 | E34: 0 | F34: 0.72 | G34: =SUM(C34:F34) -> 0.94 | H34: =1-G34 -> 0.06 | I34: 0 | J34: 0 | K34: 0.18 | L34: Não
A35: Cachaça | B35: 20 | C35: 0 | D35: 0 | E35: 0 | F35: 0 | G35: 0 | H35: 1 | I35: 0 | J35: =40%*5 -> 2 | K35: 0 | L35: Não
A36: Café Expresso | B36: 0 | C36: 0.01 | D36: 0.03 | E36: 0 | F36: 0.06 | G36: 0.1 | H36: 0.9 | I36: 0.01 | J36: 0.01 | K36: 0 | L36: Não
A37: Café Solúvel | B37: 90 | C37: 0 | D37: 0.15 | E37: 0 | F37: 0.8 | G37: 0.95 | H37: 0.05 | I37: 0 | J37: 0 | K37: 0.01 | L37: Não
A38: Caqui | B38: 0 | C38: 0.16 | D38: 0 | E38: 0 | F38: 0.02 | G38: 0.18 | H38: 0.82 | I38: 0.19 | J38: 0.23 | K38: 0.01 | L38: Não
A39: Cenoura | B39: 0 | C39: 0.08 | D39: 0 | E39: 0 | F39: 0.06 | G39: 0.14 | H39: 0.86 | I39: 0.06 | J39: 0.075 | K39: 0.01 | L39: Não
A40: Cereja | B40: 0 | C40: 0.12 | D40: 0 | E40: 0 | F40: 0.035 | G40: 0.155 | H40: 0.845 | I40: 0.14 | J40: 0.17 | K40: 0 | L40: Não
A41: Cereja Em Calda | B41: 0 | C41: 0.115 | D41: 0.005 | E41: 0 | F41: 0.025 | G41: 0.145 | H41: 0.855 | I41: 0.13 | J41: 0.16 | K41: 0.008 | L41: Não
A42: Chocolate Amargo 60% | B42: 95 | C42: 0.4 | D42: 0.35 | E42: 0 | F42: 0.25 | G42: 1 | H42: 0 | I42: 0.4 | J42: 0.4 | K42: 0.084 | L42: Não
A43: Chocolate Amargo 70% | B43: 175 | C43: 0.3 | D43: 0.38 | E43: 0 | F43: 0.32 | G43: 1 | H43: 0 | I43: 0.58 | J43: 0 | K43: 0.05 | L43: Não
...

Sheet Catálogo Geral
A1: PAINEL GERENCIAL E CATÁLOGO DE RECEITAS DE GELATO
A2: Categoria (Aba Receitas) | B2: Total Receitas | C2: Status Ok | D2: Status Revisar | E2: % Conformidade | F2: Peso ≠ 1.000 g | G2: Custo Médio/Kg (R$) | H2: Menor Custo/Kg (R$) | I2: Maior Custo/Kg (R$) | J2: Preço Médio Pote 500g (R$)
A3: Gelatos de Leite | B3: =COUNTIF($B$14:$B$500, A3) -> 60 | C3: =COUNTIFS($B$14:$B$500, A3, $S$14:$S$500, "Ok") -> 31 | D3: =COUNTIFS($B$14:$B$500, A3, $S$14:$S$500, "Revisar") -> 29 | E3: =IFERROR(C3/B3, 0) -> 0.51666667 | F3: =COUNTIFS($B$14:$B$500, A3, $E$14:$E$500, "<>1.000 g (Padrão)") -> 52 | G3: =IFERROR(AVERAGEIF($B$14:$B$500, A3, $F$14:$F$500), 0) -> 20.881075 | H3: =IFERROR(MINIFS($F$14:$F$500, $B$14:$B$500, A3, $F$14:$F$500, ">0"), 0) -> 8.8261682 | I3: =IFERROR(MAXIFS($F$14:$F$500, $B$14:$B$500, A3), 0) -> 47.080042 | J3: =IFERROR(AVERAGEIF($B$14:$B$500, A3, $H$14:$H$500), 0) -> 39.636651
A4: Gelatos de Leite com Fruta | B4: =COUNTIF($B$14:$B$500, A4) -> 10 | C4: =COUNTIFS($B$14:$B$500, A4, $S$14:$S$500, "Ok") -> 2 | D4: =COUNTIFS($B$14:$B$500, A4, $S$14:$S$500, "Revisar") -> 8 | E4: =IFERROR(C4/B4, 0) -> 0.2 | F4: =COUNTIFS($B$14:$B$500, A4, $E$14:$E$500, "<>1.000 g (Padrão)") -> 9 | G4: =IFERROR(AVERAGEIF($B$14:$B$500, A4, $F$14:$F$500), 0) -> 14.629915 | H4: =IFERROR(MINIFS($F$14:$F$500, $B$14:$B$500, A4, $F$14:$F$500, ">0"), 0) -> 6.7196896 | I4: =IFERROR(MAXIFS($F$14:$F$500, $B$14:$B$500, A4), 0) -> 25.941849 | J4: =IFERROR(AVERAGEIF($B$14:$B$500, A4, $H$14:$H$500), 0) -> 34.46185
A5: Sorbets | B5: =COUNTIF($B$14:$B$500, A5) -> 26 | C5: =COUNTIFS($B$14:$B$500, A5, $S$14:$S$500, "Ok") -> 9 | D5: =COUNTIFS($B$14:$B$500, A5, $S$14:$S$500, "Revisar") -> 17 | E5: =IFERROR(C5/B5, 0) -> 0.34615385 | F5: =COUNTIFS($B$14:$B$500, A5, $E$14:$E$500, "<>1.000 g (Padrão)") -> 17 | G5: =IFERROR(AVERAGEIF($B$14:$B$500, A5, $F$14:$F$500), 0) -> 8.5329235 | H5: =IFERROR(MINIFS($F$14:$F$500, $B$14:$B$500, A5, $F$14:$F$500, ">0"), 0) -> 3.477534 | I5: =IFERROR(MAXIFS($F$14:$F$500, $B$14:$B$500, A5), 0) -> 28.195 | J5: =IFERROR(AVERAGEIF($B$14:$B$500, A5, $H$14:$H$500), 0) -> 29.414672
A6: Chocolate base água | B6: =COUNTIF($B$14:$B$500, A6) -> 3 | C6: =COUNTIFS($B$14:$B$500, A6, $S$14:$S$500, "Ok") -> 0 | D6: =COUNTIFS($B$14:$B$500, A6, $S$14:$S$500, "Revisar") -> 3 | E6: =IFERROR(C6/B6, 0) -> 0 | F6: =COUNTIFS($B$14:$B$500, A6, $E$14:$E$500, "<>1.000 g (Padrão)") -> 3 | G6: =IFERROR(AVERAGEIF($B$14:$B$500, A6, $F$14:$F$500), 0) -> 20.942898 | H6: =IFERROR(MINIFS($F$14:$F$500, $B$14:$B$500, A6, $F$14:$F$500, ">0"), 0) -> 2.9757576 | I6: =IFERROR(MAXIFS($F$14:$F$500, $B$14:$B$500, A6), 0) -> 38.935354 | J6: =IFERROR(AVERAGEIF($B$14:$B$500, A6, $H$14:$H$500), 0) -> 39.687829
A7: Vegano | B7: =COUNTIF($B$14:$B$500, A7) -> 9 | C7: =COUNTIFS($B$14:$B$500, A7, $S$14:$S$500, "Ok") -> 8 | D7: =COUNTIFS($B$14:$B$500, A7, $S$14:$S$500, "Revisar") -> 1 | E7: =IFERROR(C7/B7, 0) -> 0.88888889 | F7: =COUNTIFS($B$14:$B$500, A7, $E$14:$E$500, "<>1.000 g (Padrão)") -> 9 | G7: =IFERROR(AVERAGEIF($B$14:$B$500, A7, $F$14:$F$500), 0) -> 25.780519 | H7: =IFERROR(MINIFS($F$14:$F$500, $B$14:$B$500, A7, $F$14:$F$500, ">0"), 0) -> 7.8612774 | I7: =IFERROR(MAXIFS($F$14:$F$500, $B$14:$B$500, A7), 0) -> 43.030938 | J7: =IFERROR(AVERAGEIF($B$14:$B$500, A7, $H$14:$H$500), 0) -> 43.692483
A8: Alcoólicos | B8: =COUNTIF($B$14:$B$500, A8) -> 11 | C8: =COUNTIFS($B$14:$B$500, A8, $S$14:$S$500, "Ok") -> 4 | D8: =COUNTIFS($B$14:$B$500, A8, $S$14:$S$500, "Revisar") -> 7 | E8: =IFERROR(C8/B8, 0) -> 0.36363636 | F8: =COUNTIFS($B$14:$B$500, A8, $E$14:$E$500, "<>1.000 g (Padrão)") -> 7 | G8: =IFERROR(AVERAGEIF($B$14:$B$500, A8, $F$14:$F$500), 0) -> 21.827533 | H8: =IFERROR(MINIFS($F$14:$F$500, $B$14:$B$500, A8, $F$14:$F$500, ">0"), 0) -> 11.550304 | I8: =IFERROR(MAXIFS($F$14:$F$500, $B$14:$B$500, A8), 0) -> 59.029 | J8: =IFERROR(AVERAGEIF($B$14:$B$500, A8, $H$14:$H$500), 0) -> 40.420143
A9: Gelatos Proteicos | B9: =COUNTIF($B$14:$B$500, A9) -> 12 | C9: =COUNTIFS($B$14:$B$500, A9, $S$14:$S$500, "Ok") -> 8 | D9: =COUNTIFS($B$14:$B$500, A9, $S$14:$S$500, "Revisar") -> 4 | E9: =IFERROR(C9/B9, 0) -> 0.66666667 | F9: =COUNTIFS($B$14:$B$500, A9, $E$14:$E$500, "<>1.000 g (Padrão)") -> 11 | G9: =IFERROR(AVERAGEIF($B$14:$B$500, A9, $F$14:$F$500), 0) -> 27.929782 | H9: =IFERROR(MINIFS($F$14:$F$500, $B$14:$B$500, A9, $F$14:$F$500, ">0"), 0) -> 18.995584 | I9: =IFERROR(MAXIFS($F$14:$F$500, $B$14:$B$500, A9), 0) -> 45.105865 | J9: =IFERROR(AVERAGEIF($B$14:$B$500, A9, $H$14:$H$500), 0) -> 45.471674
A10: Zero | B10: =COUNTIF($B$14:$B$500, A10) -> 46 | C10: =COUNTIFS($B$14:$B$500, A10, $S$14:$S$500, "Ok") -> 34 | D10: =COUNTIFS($B$14:$B$500, A10, $S$14:$S$500, "Revisar") -> 12 | E10: =IFERROR(C10/B10, 0) -> 0.73913043 | F10: =COUNTIFS($B$14:$B$500, A10, $E$14:$E$500, "<>1.000 g (Padrão)") -> 36 | G10: =IFERROR(AVERAGEIF($B$14:$B$500, A10, $F$14:$F$500), 0) -> 19.40791 | H10: =IFERROR(MINIFS($F$14:$F$500, $B$14:$B$500, A10, $F$14:$F$500, ">0"), 0) -> 8.3033419 | I10: =IFERROR(MAXIFS($F$14:$F$500, $B$14:$B$500, A10), 0) -> 53.17012 | J10: =IFERROR(AVERAGEIF($B$14:$B$500, A10, $H$14:$H$500), 0) -> 38.417144
A11: Total / Média Geral | B11: =SUM(B3:B10) -> 177 | C11: =SUM(C3:C10) -> 96 | D11: =SUM(D3:D10) -> 81 | E11: =IFERROR(C11/B11, 0) -> 0.54237288 | F11: =SUM(F3:F10) -> 144 | G11: =IFERROR(AVERAGE(F14:F500), 0) -> 19.118063 | H11: =IFERROR(MIN(H3:H10), 0) -> 2.9757576 | I11: =IFERROR(MAX(I3:I10), 0) -> 59.029 | J11: =IFERROR(AVERAGE(H14:H500), 0) -> 38.177204
A13: Receita | B13: Categoria | C13: Nº Insumos | D13: Peso Receita (g) | E13: Padronização 1kg | F13: Custo / Kg (R$) | G13: Custo Bola 60g (R$) | H13: Preço Sugerido Pote 500g (R$) | I13: Açúcares (%) | J13: Gorduras (%) | K13: SLNG (%) | L13: Outros Sólidos (%) | M13: Sólidos Totais (%) | N13: Água (%) | O13: POD | P13: PAC | Q13: Proteína (%) | R13: Temp. Serviço (°C) | S13: Status Balanceamento
A14: =IFERROR(__xludf.DUMMYFUNCTION("UNIQUE(FILTER(Receitas!A2:A3500, Receitas!A2:A3500<>""""))"),"Fior di Latte (Direto ao Ponto)") -> Fior di Latte (Direto ao Ponto) | B14: {=IF(A14:A500="", "", VLOOKUP(A14:A500, Receitas!A2:D3500, 4, FALSE))} -> Gelatos de Leite | C14: {=IF(A14:A500="", "", COUNTIF(Receitas!A2:A3500, A14:A500))} -> 8 | D14: {=IF(A14:A500="", "", SUMIF(Receitas!A2:A3500, A14:A500, Receitas!C2:C3500))} -> 1001 | E14: {=IF(A14:A500="", "", IF(ROUND(D14:D500,0)=1000, "1.000 g (Padrão)", "Diferente (" & ROUND(D14:D500, 0) & " g)"))} -> Diferente (1001 g) | F14: {=IF(A14:A500="", "", SUMIF(Receitas!A2:A3500, A14:A500, Receitas!E2:E3500) * 1000 / D14:D500)} -> 11.703796 | G14: {=IF(A14:A500="", "", F14:F500 * 0.06)} -> 0.70222777 | H14: {=IF(A14:A500="", "", ((F14:F500 * ('Conversor Custo K|G'!$F$24/1000) + 'Conversor Custo K|G'!$H$24) + 'Conversor Custo K|G'!$C$11) / ((1 - 'Conversor Custo K|G'!$C$13/100) * (1 - 'Conversor Custo K|G'!$C$14/100)))} -> 32.039566 | I14: {=IF(A14:A500="", "", SUMIF(Receitas!A2:A3500, A14:A500, Receitas!F2:F3500) / D14:D500)} -> 0.17592408 | J14: {=IF(A14:A500="", "", SUMIF(Receitas!A2:A3500, A14:A500, Receitas!G2:G3500) / D14:D500)} -> 0.074125874 | K14: {=IF(A14:A500="", "", SUMIF(Receitas!A2:A3500, A14:A500, Receitas!H2:H3500) / D14:D500)} -> 0.10834166 | L14: {=IF(A14:A500="", "", SUMIF(Receitas!A2:A3500, A14:A500, Receitas!I2:I3500) / D14:D500)} -> 0.005994006 | M14: {=IF(A14:A500="", "", I14:I500 + J14:J500 + K14:K500 + L14:L500)} -> 0.36438561 | N14: {=IF(A14:A500="", "", 1 - M14:M500)} -> 0.63561439 | O14: {=IF(A14:A500="", "", 1000 * SUMIF(Receitas!A2:A3500, A14:A500, Receitas!J2:J3500) / D14:D500)} -> 163.28272 | P14: {=IF(A14:A500="", "", 1000 * SUMIF(Receitas!A2:A3500, A14:A500, Receitas!K2:K3500) / D14:D500)} -> 249.55045 | Q14: {=IF(A14:A500="", "", SUMIF(Receitas!A2:A3500, A14:A500, Receitas!L2:L3500) / D14:D500)} -> 0.041458541 | R14: {=IF(A14:A500="", "", IF((B14:B500="Chocolate base água")+(B14:B500="Vegano")>0, P14:P500/20, IF(B14:B500="Gelatos de Leite com Fruta", P14:P500/24, P14:P500/25)))} -> 9.982018 | S14: {=IF(A14="","", IF( (ROUND(I14,4) < INDEX('Tabela de ingredientes'!$O$1:$V$30, SWITCH(B14, "Gelatos de Leite", 7, "Sorbets", 10, "Gelatos de Leite com Fruta", 13, "Chocolate base água", 16, "Vegano", 19, "Alcoólicos", 22, "Zero", 25, "Gelatos Proteicos", 28, 7), 1)) + (ROUND(I14,4) > INDEX('Tabela de ingredientes'!$O$1:$V$30, SWITCH(B14, "Gelatos de Leite", 8, "Sorbets", 11, "Gelatos de Leite com Fruta", 14, "Chocolate base água", 17, "Vegano", 20, "Alcoólicos", 23, "Zero", 26, "Gelatos Proteicos", 29, 8), 1)) + (ROUND(J14,4) < INDEX('Tabela de ingredientes'!$O$1:$V$30, SWITCH(B14, "Gelatos de Leite", 7, "Sorbets", 10, "Gelatos de Leite com Fruta", 13, "Chocolate base água", 16, "Vegano", 19, "Alcoólicos", 22, "Zero", 25, "Gelatos Proteicos", 28, 7), 2)) + (ROUND(J14,4) > INDEX('Tabela de ingredientes'!$O$1:$V$30, SWITCH(B14, "Gelatos de Leite", 8, "Sorbets", 11, "Gelatos de Leite com Fruta", 14, "Chocolate base água", 17, "Vegano", 20, "Alcoólicos", 23, "Zero", 26, "Gelatos Proteicos", 29, 8), 2)) + (ROUND(K14,4) < INDEX('Tabela de ingredientes'!$O$1:$V$30, SWITCH(B14, "Gelatos de Leite", 7, "Sorbets", 10, "Gelatos de Leite com Fruta", 13, "Chocolate base água", 16, "Vegano", 19, "Alcoólicos", 22, "Zero", 25, "Gelatos Proteicos", 28, 7), 3)) + (ROUND(K14,4) > INDEX('Tabela de ingredientes'!$O$1:$V$30, SWITCH(B14, "Gelatos de Leite", 8, "Sorbets", 11, "Gelatos de Leite com Fruta", 14, "Chocolate base água", 17, "Vegano", 20, "Alcoólicos", 23, "Zero", 26, "Gelatos Proteicos", 29, 8), 3)) + (ROUND(L14,4) < INDEX('Tabela de ingredientes'!$O$1:$V$30, SWITCH(B14, "Gelatos de Leite", 7, "Sorbets", 10, "Gelatos de Leite com Fruta", 13, "Chocolate base água", 16, "Vegano", 19, "Alcoólicos", 22, "Zero", 25, "Gelatos Proteicos", 28, 7), 4)) + (ROUND(L14,4) > INDEX('Tabela de ingredientes'!$O$1:$V$30, SWITCH(B14, "Gelatos de Leite", 8, "Sorbets", 11, "Gelatos de Leite com Fruta", 14, "Chocolate base água", 17, "Vegano", 20, "Alcoólicos", 23, "Zero", 26, "Gelatos Proteicos", 29, 8), 4)) + (ROUND(M14,4) < INDEX('Tabela de ingredientes'!$O$1:$V$30, SWITCH(B14, "Gelatos de Leite", 7, "Sorbets", 10, "Gelatos de Leite com Fruta", 13, "Chocolate base água", 16, "Vegano", 19, "Alcoólicos", 22, "Zero", 25, "Gelatos Proteicos", 28, 7), 5)) + (ROUND(M14,4) > INDEX('Tabela de ingredientes'!$O$1:$V$30, SWITCH(B14, "Gelatos de Leite", 8, "Sorbets", 11, "Gelatos de Leite com Fruta", 14, "Chocolate base água", 17, "Vegano", 20, "Alcoólicos", 23, "Zero", 26, "Gelatos Proteicos", 29, 8), 5)) + (ROUND(N14,4) < INDEX('Tabela de ingredientes'!$O$1:$V$30, SWITCH(B14, "Gelatos de Leite", 7, "Sorbets", 10, "Gelatos de Leite com Fruta", 13, "Chocolate base água", 16, "Vegano", 19, "Alcoólicos", 22, "Zero", 25, "Gelatos Proteicos", 28, 7), 6)) + (ROUND(N14,4) > INDEX('Tabela de ingredientes'!$O$1:$V$30, SWITCH(B14, "Gelatos de Leite", 8, "Sorbets", 11, "Gelatos de Leite com Fruta", 14, "Chocolate base água", 17, "Vegano", 20, "Alcoólicos", 23, "Zero", 26, "Gelatos Proteicos", 29, 8), 6)) + (ROUND(O14,4) < INDEX('Tabela de ingredientes'!$O$1:$V$30, SWITCH(B14, "Gelatos de Leite", 7, "Sorbets", 10, "Gelatos de Leite com Fruta", 13, "Chocolate base água", 16, "Vegano", 19, "Alcoólicos", 22, "Zero", 25, "Gelatos Proteicos", 28, 7), 7)) + (ROUND(O14,4) > INDEX('Tabela de ingredientes'!$O$1:$V$30, SWITCH(B14, "Gelatos de Leite", 8, "Sorbets", 11, "Gelatos de Leite com Fruta", 14, "Chocolate base água", 17, "Vegano", 20, "Alcoólicos", 23, "Zero", 26, "Gelatos Proteicos", 29, 8), 7)) + (ROUND(P14,4) < INDEX('Tabela de ingredientes'!$O$1:$V$30, SWITCH(B14, "Gelatos de Leite", 7, "Sorbets", 10, "Gelatos de Leite com Fruta", 13, "Chocolate base água", 16, "Vegano", 19, "Alcoólicos", 22, "Zero", 25, "Gelatos Proteicos", 28, 7), 8)) + (ROUND(P14,4) > INDEX('Tabela de ingredientes'!$O$1:$V$30, SWITCH(B14, "Gelatos de Leite", 8, "Sorbets", 11, "Gelatos de Leite com Fruta", 14, "Chocolate base água", 17, "Vegano", 20, "Alcoólicos", 23, "Zero", 26, "Gelatos Proteicos", 29, 8), 8)) + IF(B14="Gelatos Proteicos", (ROUND(Q14,4)<'Tabela de ingredientes'!$W$28)+(ROUND(Q14,4)>'Tabela de ingredientes'!$W$29), 0) = 0, "Ok", "Revisar"))} -> Ok
A15: =IFERROR(__xludf.DUMMYFUNCTION("""COMPUTED_VALUE"""),"Café Bianco Flocado (Direto ao Ponto)") -> Café Bianco Flocado (Direto ao Ponto) | B15: Gelatos de Leite | C15: 8 | D15: 1001 | E15: Diferente (1001 g) | F15: 12.423077 | G15: 0.74538462 | H15: 32.634997 | I15: 0.17592408 | J15: 0.08986014 | K15: 0.10684316 | L15: 0.005994006 | M15: 0.37862138 | N15: 0.62137862 | O15: 163.16284 | P15: 249.05095 | Q15: 0.040909091 | R15: 9.962038 | S15: {=IF(A15="","", IF( (ROUND(I15,4) < INDEX('Tabela de ingredientes'!$O$1:$V$30, SWITCH(B15, "Gelatos de Leite", 7, "Sorbets", 10, "Gelatos de Leite com Fruta", 13, "Chocolate base água", 16, "Vegano", 19, "Alcoólicos", 22, "Zero", 25, "Gelatos Proteicos", 28, 7), 1)) + (ROUND(I15,4) > INDEX('Tabela de ingredientes'!$O$1:$V$30, SWITCH(B15, "Gelatos de Leite", 8, "Sorbets", 11, "Gelatos de Leite com Fruta", 14, "Chocolate base água", 17, "Vegano", 20, "Alcoólicos", 23, "Zero", 26, "Gelatos Proteicos", 29, 8), 1)) + (ROUND(J15,4) < INDEX('Tabela de ingredientes'!$O$1:$V$30, SWITCH(B15, "Gelatos de Leite", 7, "Sorbets", 10, "Gelatos de Leite com Fruta", 13, "Chocolate base água", 16, "Vegano", 19, "Alcoólicos", 22, "Zero", 25, "Gelatos Proteicos", 28, 7), 2)) + (ROUND(J15,4) > INDEX('Tabela de ingredientes'!$O$1:$V$30, SWITCH(B15, "Gelatos de Leite", 8, "Sorbets", 11, "Gelatos de Leite com Fruta", 14, "Chocolate base água", 17, "Vegano", 20, "Alcoólicos", 23, "Zero", 26, "Gelatos Proteicos", 29, 8), 2)) + (ROUND(K15,4) < INDEX('Tabela de ingredientes'!$O$1:$V$30, SWITCH(B15, "Gelatos de Leite", 7, "Sorbets", 10, "Gelatos de Leite com Fruta", 13, "Chocolate base água", 16, "Vegano", 19, "Alcoólicos", 22, "Zero", 25, "Gelatos Proteicos", 28, 7), 3)) + (ROUND(K15,4) > INDEX('Tabela de ingredientes'!$O$1:$V$30, SWITCH(B15, "Gelatos de Leite", 8, "Sorbets", 11, "Gelatos de Leite com Fruta", 14, "Chocolate base água", 17, "Vegano", 20, "Alcoólicos", 23, "Zero", 26, "Gelatos Proteicos", 29, 8), 3)) + (ROUND(L15,4) < INDEX('Tabela de ingredientes'!$O$1:$V$30, SWITCH(B15, "Gelatos de Leite", 7, "Sorbets", 10, "Gelatos de Leite com Fruta", 13, "Chocolate base água", 16, "Vegano", 19, "Alcoólicos", 22, "Zero", 25, "Gelatos Proteicos", 28, 7), 4)) + (ROUND(L15,4) > INDEX('Tabela de ingredientes'!$O$1:$V$30, SWITCH(B15, "Gelatos de Leite", 8, "Sorbets", 11, "Gelatos de Leite com Fruta", 14, "Chocolate base água", 17, "Vegano", 20, "Alcoólicos", 23, "Zero", 26, "Gelatos Proteicos", 29, 8), 4)) + (ROUND(M15,4) < INDEX('Tabela de ingredientes'!$O$1:$V$30, SWITCH(B15, "Gelatos de Leite", 7, "Sorbets", 10, "Gelatos de Leite com Fruta", 13, "Chocolate base água", 16, "Vegano", 19, "Alcoólicos", 22, "Zero", 25, "Gelatos Proteicos", 28, 7), 5)) + (ROUND(M15,4) > INDEX('Tabela de ingredientes'!$O$1:$V$30, SWITCH(B15, "Gelatos de Leite", 8, "Sorbets", 11, "Gelatos de Leite com Fruta", 14, "Chocolate base água", 17, "Vegano", 20, "Alcoólicos", 23, "Zero", 26, "Gelatos Proteicos", 29, 8), 5)) + (ROUND(N15,4) < INDEX('Tabela de ingredientes'!$O$1:$V$30, SWITCH(B15, "Gelatos de Leite", 7, "Sorbets", 10, "Gelatos de Leite com Fruta", 13, "Chocolate base água", 16, "Vegano", 19, "Alcoólicos", 22, "Zero", 25, "Gelatos Proteicos", 28, 7), 6)) + (ROUND(N15,4) > INDEX('Tabela de ingredientes'!$O$1:$V$30, SWITCH(B15, "Gelatos de Leite", 8, "Sorbets", 11, "Gelatos de Leite com Fruta", 14, "Chocolate base água", 17, "Vegano", 20, "Alcoólicos", 23, "Zero", 26, "Gelatos Proteicos", 29, 8), 6)) + (ROUND(O15,4) < INDEX('Tabela de ingredientes'!$O$1:$V$30, SWITCH(B15, "Gelatos de Leite", 7, "Sorbets", 10, "Gelatos de Leite com Fruta", 13, "Chocolate base água", 16, "Vegano", 19, "Alcoólicos", 22, "Zero", 25, "Gelatos Proteicos", 28, 7), 7)) + (ROUND(O15,4) > INDEX('Tabela de ingredientes'!$O$1:$V$30, SWITCH(B15, "Gelatos de Leite", 8, "Sorbets", 11, "Gelatos de Leite com Fruta", 14, "Chocolate base água", 17, "Vegano", 20, "Alcoólicos", 23, "Zero", 26, "Gelatos Proteicos", 29, 8), 7)) + (ROUND(P15,4) < INDEX('Tabela de ingredientes'!$O$1:$V$30, SWITCH(B15, "Gelatos de Leite", 7, "Sorbets", 10, "Gelatos de Leite com Fruta", 13, "Chocolate base água", 16, "Vegano", 19, "Alcoólicos", 22, "Zero", 25, "Gelatos Proteicos", 28, 7), 8)) + (ROUND(P15,4) > INDEX('Tabela de ingredientes'!$O$1:$V$30, SWITCH(B15, "Gelatos de Leite", 8, "Sorbets", 11, "Gelatos de Leite com Fruta", 14, "Chocolate base água", 17, "Vegano", 20, "Alcoólicos", 23, "Zero", 26, "Gelatos Proteicos", 29, 8), 8)) + IF(B15="Gelatos Proteicos", (ROUND(Q15,4)<'Tabela de ingredientes'!$W$28)+(ROUND(Q15,4)>'Tabela de ingredientes'!$W$29), 0) = 0, "Ok", "Revisar"))} -> Ok
A16: =IFERROR(__xludf.DUMMYFUNCTION("""COMPUTED_VALUE"""),"Chocolate com Gostosuras (Direto ao Ponto)") -> Chocolate com Gostosuras (Direto ao Ponto) | B16: Gelatos de Leite | C16: 9 | D16: 1000 | E16: 1.000 g (Padrão) | F16: 23.8625 | G16: 1.43175 | H16: 42.104719 | I16: 0.17 | J16: 0.07885 | K16: 0.0906 | L16: 0.0558 | M16: 0.39525 | N16: 0.60475 | O16: 191.143 | P16: 235.55 | Q16: 0.04416 | R16: 9.422 | S16: {=IF(A16="","", IF( (ROUND(I16,4) < INDEX('Tabela de ingredientes'!$O$1:$V$30, SWITCH(B16, "Gelatos de Leite", 7, "Sorbets", 10, "Gelatos de Leite com Fruta", 13, "Chocolate base água", 16, "Vegano", 19, "Alcoólicos", 22, "Zero", 25, "Gelatos Proteicos", 28, 7), 1)) + (ROUND(I16,4) > INDEX('Tabela de ingredientes'!$O$1:$V$30, SWITCH(B16, "Gelatos de Leite", 8, "Sorbets", 11, "Gelatos de Leite com Fruta", 14, "Chocolate base água", 17, "Vegano", 20, "Alcoólicos", 23, "Zero", 26, "Gelatos Proteicos", 29, 8), 1)) + (ROUND(J16,4) < INDEX('Tabela de ingredientes'!$O$1:$V$30, SWITCH(B16, "Gelatos de Leite", 7, "Sorbets", 10, "Gelatos de Leite com Fruta", 13, "Chocolate base água", 16, "Vegano", 19, "Alcoólicos", 22, "Zero", 25, "Gelatos Proteicos", 28, 7), 2)) + (ROUND(J16,4) > INDEX('Tabela de ingredientes'!$O$1:$V$30, SWITCH(B16, "Gelatos de Leite", 8, "Sorbets", 11, "Gelatos de Leite com Fruta", 14, "Chocolate base água", 17, "Vegano", 20, "Alcoólicos", 23, "Zero", 26, "Gelatos Proteicos", 29, 8), 2)) + (ROUND(K16,4) < INDEX('Tabela de ingredientes'!$O$1:$V$30, SWITCH(B16, "Gelatos de Leite", 7, "Sorbets", 10, "Gelatos de Leite com Fruta", 13, "Chocolate base água", 16, "Vegano", 19, "Alcoólicos", 22, "Zero", 25, "Gelatos Proteicos", 28, 7), 3)) + (ROUND(K16,4) > INDEX('Tabela de ingredientes'!$O$1:$V$30, SWITCH(B16, "Gelatos de Leite", 8, "Sorbets", 11, "Gelatos de Leite com Fruta", 14, "Chocolate base água", 17, "Vegano", 20, "Alcoólicos", 23, "Zero", 26, "Gelatos Proteicos", 29, 8), 3)) + (ROUND(L16,4) < INDEX('Tabela de ingredientes'!$O$1:$V$30, SWITCH(B16, "Gelatos de Leite", 7, "Sorbets", 10, "Gelatos de Leite com Fruta", 13, "Chocolate base água", 16, "Vegano", 19, "Alcoólicos", 22, "Zero", 25, "Gelatos Proteicos", 28, 7), 4)) + (ROUND(L16,4) > INDEX('Tabela de ingredientes'!$O$1:$V$30, SWITCH(B16, "Gelatos de Leite", 8, "Sorbets", 11, "Gelatos de Leite com Fruta", 14, "Chocolate base água", 17, "Vegano", 20, "Alcoólicos", 23, "Zero", 26, "Gelatos Proteicos", 29, 8), 4)) + (ROUND(M16,4) < INDEX('Tabela de ingredientes'!$O$1:$V$30, SWITCH(B16, "Gelatos de Leite", 7, "Sorbets", 10, "Gelatos de Leite com Fruta", 13, "Chocolate base água", 16, "Vegano", 19, "Alcoólicos", 22, "Zero", 25, "Gelatos Proteicos", 28, 7), 5)) + (ROUND(M16,4) > INDEX('Tabela de ingredientes'!$O$1:$V$30, SWITCH(B16, "Gelatos de Leite", 8, "Sorbets", 11, "Gelatos de Leite com Fruta", 14, "Chocolate base água", 17, "Vegano", 20, "Alcoólicos", 23, "Zero", 26, "Gelatos Proteicos", 29, 8), 5)) + (ROUND(N16,4) < INDEX('Tabela de ingredientes'!$O$1:$V$30, SWITCH(B16, "Gelatos de Leite", 7, "Sorbets", 10, "Gelatos de Leite com Fruta", 13, "Chocolate base água", 16, "Vegano", 19, "Alcoólicos", 22, "Zero", 25, "Gelatos Proteicos", 28, 7), 6)) + (ROUND(N16,4) > INDEX('Tabela de ingredientes'!$O$1:$V$30, SWITCH(B16, "Gelatos de Leite", 8, "Sorbets", 11, "Gelatos de Leite com Fruta", 14, "Chocolate base água", 17, "Vegano", 20, "Alcoólicos", 23, "Zero", 26, "Gelatos Proteicos", 29, 8), 6)) + (ROUND(O16,4) < INDEX('Tabela de ingredientes'!$O$1:$V$30, SWITCH(B16, "Gelatos de Leite", 7, "Sorbets", 10, "Gelatos de Leite com Fruta", 13, "Chocolate base água", 16, "Vegano", 19, "Alcoólicos", 22, "Zero", 25, "Gelatos Proteicos", 28, 7), 7)) + (ROUND(O16,4) > INDEX('Tabela de ingredientes'!$O$1:$V$30, SWITCH(B16, "Gelatos de Leite", 8, "Sorbets", 11, "Gelatos de Leite com Fruta", 14, "Chocolate base água", 17, "Vegano", 20, "Alcoólicos", 23, "Zero", 26, "Gelatos Proteicos", 29, 8), 7)) + (ROUND(P16,4) < INDEX('Tabela de ingredientes'!$O$1:$V$30, SWITCH(B16, "Gelatos de Leite", 7, "Sorbets", 10, "Gelatos de Leite com Fruta", 13, "Chocolate base água", 16, "Vegano", 19, "Alcoólicos", 22, "Zero", 25, "Gelatos Proteicos", 28, 7), 8)) + (ROUND(P16,4) > INDEX('Tabela de ingredientes'!$O$1:$V$30, SWITCH(B16, "Gelatos de Leite", 8, "Sorbets", 11, "Gelatos de Leite com Fruta", 14, "Chocolate base água", 17, "Vegano", 20, "Alcoólicos", 23, "Zero", 26, "Gelatos Proteicos", 29, 8), 8)) + IF(B16="Gelatos Proteicos", (ROUND(Q16,4)<'Tabela de ingredientes'!$W$28)+(ROUND(Q16,4)>'Tabela de ingredientes'!$W$29), 0) = 0, "Ok", "Revisar"))} -> Ok
A17: =IFERROR(__xludf.DUMMYFUNCTION("""COMPUTED_VALUE"""),"Crema (Direto ao Ponto)") -> Crema (Direto ao Ponto) | B17: Gelatos de Leite | C17: 9 | D17: 1005 | E17: Diferente (1005 g) | F17: 16.630348 | G17: 0.9978209 | H17: 36.117838 | I17: 0.15084577 | J17: 0.088159204 | K17: 0.10432836 | L17: 0.019303483 | M17: 0.36263682 | N17: 0.63736318 | O17: 152.61493 | P17: 229.70149 | Q17: 0.052616915 | R17: 9.1880597 | S17: {=IF(A17="","", IF( (ROUND(I17,4) < INDEX('Tabela de ingredientes'!$O$1:$V$30, SWITCH(B17, "Gelatos de Leite", 7, "Sorbets", 10, "Gelatos de Leite com Fruta", 13, "Chocolate base água", 16, "Vegano", 19, "Alcoólicos", 22, "Zero", 25, "Gelatos Proteicos", 28, 7), 1)) + (ROUND(I17,4) > INDEX('Tabela de ingredientes'!$O$1:$V$30, SWITCH(B17, "Gelatos de Leite", 8, "Sorbets", 11, "Gelatos de Leite com Fruta", 14, "Chocolate base água", 17, "Vegano", 20, "Alcoólicos", 23, "Zero", 26, "Gelatos Proteicos", 29, 8), 1)) + (ROUND(J17,4) < INDEX('Tabela de ingredientes'!$O$1:$V$30, SWITCH(B17, "Gelatos de Leite", 7, "Sorbets", 10, "Gelatos de Leite com Fruta", 13, "Chocolate base água", 16, "Vegano", 19, "Alcoólicos", 22, "Zero", 25, "Gelatos Proteicos", 28, 7), 2)) + (ROUND(J17,4) > INDEX('Tabela de ingredientes'!$O$1:$V$30, SWITCH(B17, "Gelatos de Leite", 8, "Sorbets", 11, "Gelatos de Leite com Fruta", 14, "Chocolate base água", 17, "Vegano", 20, "Alcoólicos", 23, "Zero", 26, "Gelatos Proteicos", 29, 8), 2)) + (ROUND(K17,4) < INDEX('Tabela de ingredientes'!$O$1:$V$30, SWITCH(B17, "Gelatos de Leite", 7, "Sorbets", 10, "Gelatos de Leite com Fruta", 13, "Chocolate base água", 16, "Vegano", 19, "Alcoólicos", 22, "Zero", 25, "Gelatos Proteicos", 28, 7), 3)) + (ROUND(K17,4) > INDEX('Tabela de ingredientes'!$O$1:$V$30, SWITCH(B17, "Gelatos de Leite", 8, "Sorbets", 11, "Gelatos de Leite com Fruta", 14, "Chocolate base água", 17, "Vegano", 20, "Alcoólicos", 23, "Zero", 26, "Gelatos Proteicos", 29, 8), 3)) + (ROUND(L17,4) < INDEX('Tabela de ingredientes'!$O$1:$V$30, SWITCH(B17, "Gelatos de Leite", 7, "Sorbets", 10, "Gelatos de Leite com Fruta", 13, "Chocolate base água", 16, "Vegano", 19, "Alcoólicos", 22, "Zero", 25, "Gelatos Proteicos", 28, 7), 4)) + (ROUND(L17,4) > INDEX('Tabela de ingredientes'!$O$1:$V$30, SWITCH(B17, "Gelatos de Leite", 8, "Sorbets", 11, "Gelatos de Leite com Fruta", 14, "Chocolate base água", 17, "Vegano", 20, "Alcoólicos", 23, "Zero", 26, "Gelatos Proteicos", 29, 8), 4)) + (ROUND(M17,4) < INDEX('Tabela de ingredientes'!$O$1:$V$30, SWITCH(B17, "Gelatos de Leite", 7, "Sorbets", 10, "Gelatos de Leite com Fruta", 13, "Chocolate base água", 16, "Vegano", 19, "Alcoólicos", 22, "Zero", 25, "Gelatos Proteicos", 28, 7), 5)) + (ROUND(M17,4) > INDEX('Tabela de ingredientes'!$O$1:$V$30, SWITCH(B17, "Gelatos de Leite", 8, "Sorbets", 11, "Gelatos de Leite com Fruta", 14, "Chocolate base água", 17, "Vegano", 20, "Alcoólicos", 23, "Zero", 26, "Gelatos Proteicos", 29, 8), 5)) + (ROUND(N17,4) < INDEX('Tabela de ingredientes'!$O$1:$V$30, SWITCH(B17, "Gelatos de Leite", 7, "Sorbets", 10, "Gelatos de Leite com Fruta", 13, "Chocolate base água", 16, "Vegano", 19, "Alcoólicos", 22, "Zero", 25, "Gelatos Proteicos", 28, 7), 6)) + (ROUND(N17,4) > INDEX('Tabela de ingredientes'!$O$1:$V$30, SWITCH(B17, "Gelatos de Leite", 8, "Sorbets", 11, "Gelatos de Leite com Fruta", 14, "Chocolate base água", 17, "Vegano", 20, "Alcoólicos", 23, "Zero", 26, "Gelatos Proteicos", 29, 8), 6)) + (ROUND(O17,4) < INDEX('Tabela de ingredientes'!$O$1:$V$30, SWITCH(B17, "Gelatos de Leite", 7, "Sorbets", 10, "Gelatos de Leite com Fruta", 13, "Chocolate base água", 16, "Vegano", 19, "Alcoólicos", 22, "Zero", 25, "Gelatos Proteicos", 28, 7), 7)) + (ROUND(O17,4) > INDEX('Tabela de ingredientes'!$O$1:$V$30, SWITCH(B17, "Gelatos de Leite", 8, "Sorbets", 11, "Gelatos de Leite com Fruta", 14, "Chocolate base água", 17, "Vegano", 20, "Alcoólicos", 23, "Zero", 26, "Gelatos Proteicos", 29, 8), 7)) + (ROUND(P17,4) < INDEX('Tabela de ingredientes'!$O$1:$V$30, SWITCH(B17, "Gelatos de Leite", 7, "Sorbets", 10, "Gelatos de Leite com Fruta", 13, "Chocolate base água", 16, "Vegano", 19, "Alcoólicos", 22, "Zero", 25, "Gelatos Proteicos", 28, 7), 8)) + (ROUND(P17,4) > INDEX('Tabela de ingredientes'!$O$1:$V$30, SWITCH(B17, "Gelatos de Leite", 8, "Sorbets", 11, "Gelatos de Leite com Fruta", 14, "Chocolate base água", 17, "Vegano", 20, "Alcoólicos", 23, "Zero", 26, "Gelatos Proteicos", 29, 8), 8)) + IF(B17="Gelatos Proteicos", (ROUND(Q17,4)<'Tabela de ingredientes'!$W$28)+(ROUND(Q17,4)>'Tabela de ingredientes'!$W$29), 0) = 0, "Ok", "Revisar"))} -> Ok
